Message 1:
Process exited with status 1: Traceback (most recent call last):
  File "/mnt/d/PythonProjects/AutoKaggleMaster/multi_agents/competition/bank_churn/deep_eda/deep_eda_run_code.py", line 187, in <module>
    generated_code_function()
  File "/mnt/d/PythonProjects/AutoKaggleMaster/multi_agents/competition/bank_churn/deep_eda/deep_eda_run_code.py", line 159, in generated_code_function
    sns.jointplot(data=train_data, x=x_feature, y=y_feature, hue='Exited')
  File "/home/azusa/anaconda3/envs/pipeline/lib/python3.8/site-packages/seaborn/axisgrid.py", line 2267, in jointplot
    grid.plot_marginals(marg_func, **marginal_kws)
  File "/home/azusa/anaconda3/envs/pipeline/lib/python3.8/site-packages/seaborn/axisgrid.py", line 1883, in plot_marginals
    func(x=self.x, ax=self.ax_marg_x, **kwargs)
  File "/home/azusa/anaconda3/envs/pipeline/lib/python3.8/site-packages/seaborn/distributions.py", line 1679, in kdeplot
    p._attach(ax, allowed_types=["numeric", "datetime"], log_scale=log_scale)
  File "/home/azusa/anaconda3/envs/pipeline/lib/python3.8/site-packages/seaborn/_base.py", line 1084, in _attach
    raise TypeError(err)
TypeError: The x variable is categorical, but one of ['numeric', 'datetime'] is required



