Based on the provided tool descriptions, the error in the code is clear. The `convert_data_types` function does not accept 'category' as a valid `target_type`. The most relevant code snippet causing the error is:

```python
# Convert data types in training data
train_df_clean = convert_data_types(train_df_clean, numerical_features, 'float')
train_df_clean = convert_data_types(train_df_clean, categorical_features, 'category')  # <- Error occurs here
train_df_clean = convert_data_types(train_df_clean, ['id'], 'int')

# Apply the same to the test data
test_df_clean = convert_data_types(test_df_clean, numerical_features, 'float')
test_df_clean = convert_data_types(test_df_clean, categorical_features, 'category')  # <- Error occurs here
test_df_clean = convert_data_types(test_df_clean, ['id'], 'int')
```

Within this snippet, the function `convert_data_types` is being called with an unsupported `target_type` ('category') for both the training and test datasets. The function accepts only 'int', 'float', 'str', 'bool', or 'datetime' as valid target types, leading to the `ValueError`. The error occurs specifically at the lines where 'category' is passed as the `target_type`.