Message 1:
Process exited with status 1: Traceback (most recent call last):
  File "/mnt/d/PythonProjects/AutoKaggleMaster/multi_agents/competition/obesity_risks/model_build_predict/model_build_predict_run_code.py", line 233, in <module>
    generated_code_function()
  File "/mnt/d/PythonProjects/AutoKaggleMaster/multi_agents/competition/obesity_risks/model_build_predict/model_build_predict_run_code.py", line 196, in generated_code_function
    best_model = train_and_validation_and_select_the_best_model(
  File "/mnt/d/PythonProjects/AutoKaggleMaster/multi_agents/competition/obesity_risks/model_build_predict/model_build_predict_run_code.py", line 181, in train_and_validation_and_select_the_best_model
    scores = cross_val_score(model, X, y, cv=5, scoring='accuracy')
NameError: name 'cross_val_score' is not defined



Message 2:
Process exited with status 1: Traceback (most recent call last):
  File "/mnt/d/PythonProjects/AutoKaggleMaster/multi_agents/competition/obesity_risks/model_build_predict/model_build_predict_run_code.py", line 231, in <module>
    generated_code_function()
  File "/mnt/d/PythonProjects/AutoKaggleMaster/multi_agents/competition/obesity_risks/model_build_predict/model_build_predict_run_code.py", line 196, in generated_code_function
    best_model = train_and_validation_and_select_the_best_model(
  File "/mnt/d/PythonProjects/AutoKaggleMaster/multi_agents/competition/obesity_risks/model_build_predict/model_build_predict_run_code.py", line 181, in train_and_validation_and_select_the_best_model
    scores = cross_val_score(model, X, y, cv=5, scoring='accuracy')
  File "/home/azusa/anaconda3/envs/pipeline/lib/python3.8/site-packages/sklearn/model_selection/_validation.py", line 562, in cross_val_score
    cv_results = cross_validate(
  File "/home/azusa/anaconda3/envs/pipeline/lib/python3.8/site-packages/sklearn/utils/_param_validation.py", line 214, in wrapper
    return func(*args, **kwargs)
  File "/home/azusa/anaconda3/envs/pipeline/lib/python3.8/site-packages/sklearn/model_selection/_validation.py", line 328, in cross_validate
    _warn_or_raise_about_fit_failures(results, error_score)
  File "/home/azusa/anaconda3/envs/pipeline/lib/python3.8/site-packages/sklearn/model_selection/_validation.py", line 414, in _warn_or_raise_about_fit_failures
    raise ValueError(all_fits_failed_message)
ValueError: 
All the 5 fits failed.
It is very likely that your model is misconfigured.
You can try to debug the error by setting error_score='raise'.

Below are more details about the failures:
--------------------------------------------------------------------------------
1 fits failed with the following error:
Traceback (most recent call last):
  File "/home/azusa/anaconda3/envs/pipeline/lib/python3.8/site-packages/sklearn/model_selection/_validation.py", line 729, in _fit_and_score
    estimator.fit(X_train, y_train, **fit_params)
  File "/home/azusa/anaconda3/envs/pipeline/lib/python3.8/site-packages/sklearn/base.py", line 1152, in wrapper
    return fit_method(estimator, *args, **kwargs)
  File "/home/azusa/anaconda3/envs/pipeline/lib/python3.8/site-packages/sklearn/ensemble/_forest.py", line 348, in fit
    X, y = self._validate_data(
  File "/home/azusa/anaconda3/envs/pipeline/lib/python3.8/site-packages/sklearn/base.py", line 622, in _validate_data
    X, y = check_X_y(X, y, **check_params)
  File "/home/azusa/anaconda3/envs/pipeline/lib/python3.8/site-packages/sklearn/utils/validation.py", line 1146, in check_X_y
    X = check_array(
  File "/home/azusa/anaconda3/envs/pipeline/lib/python3.8/site-packages/sklearn/utils/validation.py", line 915, in check_array
    array = _asarray_with_order(array, order=order, dtype=dtype, xp=xp)
  File "/home/azusa/anaconda3/envs/pipeline/lib/python3.8/site-packages/sklearn/utils/_array_api.py", line 380, in _asarray_with_order
    array = numpy.asarray(array, order=order, dtype=dtype)
  File "/home/azusa/anaconda3/envs/pipeline/lib/python3.8/site-packages/pandas/core/generic.py", line 1998, in __array__
    arr = np.asarray(values, dtype=dtype)
ValueError: could not convert string to float: 'no'

--------------------------------------------------------------------------------
4 fits failed with the following error:
Traceback (most recent call last):
  File "/home/azusa/anaconda3/envs/pipeline/lib/python3.8/site-packages/sklearn/model_selection/_validation.py", line 729, in _fit_and_score
    estimator.fit(X_train, y_train, **fit_params)
  File "/home/azusa/anaconda3/envs/pipeline/lib/python3.8/site-packages/sklearn/base.py", line 1152, in wrapper
    return fit_method(estimator, *args, **kwargs)
  File "/home/azusa/anaconda3/envs/pipeline/lib/python3.8/site-packages/sklearn/ensemble/_forest.py", line 348, in fit
    X, y = self._validate_data(
  File "/home/azusa/anaconda3/envs/pipeline/lib/python3.8/site-packages/sklearn/base.py", line 622, in _validate_data
    X, y = check_X_y(X, y, **check_params)
  File "/home/azusa/anaconda3/envs/pipeline/lib/python3.8/site-packages/sklearn/utils/validation.py", line 1146, in check_X_y
    X = check_array(
  File "/home/azusa/anaconda3/envs/pipeline/lib/python3.8/site-packages/sklearn/utils/validation.py", line 915, in check_array
    array = _asarray_with_order(array, order=order, dtype=dtype, xp=xp)
  File "/home/azusa/anaconda3/envs/pipeline/lib/python3.8/site-packages/sklearn/utils/_array_api.py", line 380, in _asarray_with_order
    array = numpy.asarray(array, order=order, dtype=dtype)
  File "/home/azusa/anaconda3/envs/pipeline/lib/python3.8/site-packages/pandas/core/generic.py", line 1998, in __array__
    arr = np.asarray(values, dtype=dtype)
ValueError: could not convert string to float: 'yes'




Message 3:
Process exited with status 1: Traceback (most recent call last):
  File "/mnt/d/PythonProjects/AutoKaggleMaster/multi_agents/competition/obesity_risks/model_build_predict/model_build_predict_run_code.py", line 238, in <module>
    generated_code_function()
  File "/mnt/d/PythonProjects/AutoKaggleMaster/multi_agents/competition/obesity_risks/model_build_predict/model_build_predict_run_code.py", line 203, in generated_code_function
    best_model = train_and_validation_and_select_the_best_model(
  File "/mnt/d/PythonProjects/AutoKaggleMaster/multi_agents/competition/obesity_risks/model_build_predict/model_build_predict_run_code.py", line 188, in train_and_validation_and_select_the_best_model
    scores = cross_val_score(model, X, y, cv=5, scoring='accuracy')
  File "/home/azusa/anaconda3/envs/pipeline/lib/python3.8/site-packages/sklearn/model_selection/_validation.py", line 562, in cross_val_score
    cv_results = cross_validate(
  File "/home/azusa/anaconda3/envs/pipeline/lib/python3.8/site-packages/sklearn/utils/_param_validation.py", line 214, in wrapper
    return func(*args, **kwargs)
  File "/home/azusa/anaconda3/envs/pipeline/lib/python3.8/site-packages/sklearn/model_selection/_validation.py", line 328, in cross_validate
    _warn_or_raise_about_fit_failures(results, error_score)
  File "/home/azusa/anaconda3/envs/pipeline/lib/python3.8/site-packages/sklearn/model_selection/_validation.py", line 414, in _warn_or_raise_about_fit_failures
    raise ValueError(all_fits_failed_message)
ValueError: 
All the 5 fits failed.
It is very likely that your model is misconfigured.
You can try to debug the error by setting error_score='raise'.

Below are more details about the failures:
--------------------------------------------------------------------------------
5 fits failed with the following error:
Traceback (most recent call last):
  File "/home/azusa/anaconda3/envs/pipeline/lib/python3.8/site-packages/sklearn/model_selection/_validation.py", line 729, in _fit_and_score
    estimator.fit(X_train, y_train, **fit_params)
  File "/home/azusa/anaconda3/envs/pipeline/lib/python3.8/site-packages/xgboost/core.py", line 726, in inner_f
    return func(**kwargs)
  File "/home/azusa/anaconda3/envs/pipeline/lib/python3.8/site-packages/xgboost/sklearn.py", line 1491, in fit
    raise ValueError(
ValueError: Invalid classes inferred from unique values of `y`.  Expected: [0 1 2 3 4 5 6], got ['Insufficient_Weight' 'Normal_Weight' 'Obesity_Type_I' 'Obesity_Type_II'
 'Obesity_Type_III' 'Overweight_Level_I' 'Overweight_Level_II']




